2025-09-26 16:34:54,554 - nutrition_generator.main - INFO - Démarrage de l'application
2025-09-26 16:34:54,962 - nutrition_generator.main - ERROR - Erreur fatale: Can't find a usable init.tcl in the following directories: 
    C:/Users/Eric/AppData/Local/Programs/Python/Python313/lib/tcl8.6 C:/Users/Eric/AppData/Local/Programs/Python/lib/tcl8.6 C:/Users/Eric/AppData/Local/Programs/lib/tcl8.6 C:/Users/Eric/AppData/Local/Programs/Python/library C:/Users/Eric/AppData/Local/Programs/library C:/Users/Eric/AppData/Local/Programs/tcl8.6.14/library C:/Users/Eric/AppData/Local/tcl8.6.14/library



This probably means that Tcl wasn't installed properly.
Traceback (most recent call last):
  File "c:\Users\Eric\Documents\Fiche-nutrition\nutrition_generator\main.py", line 138, in main
    app = MainWindow()
  File "c:\Users\Eric\Documents\Fiche-nutrition\nutrition_generator\gui\main_window.py", line 24, in __init__
    super().__init__()
    ~~~~~~~~~~~~~~~~^^
  File "C:\Users\Eric\Documents\Fiche-nutrition\.venv\Lib\site-packages\customtkinter\windows\ctk_tk.py", line 40, in __init__
    CTK_PARENT_CLASS.__init__(self, **pop_from_dict_by_set(kwargs, self._valid_tk_constructor_arguments))
    ~~~~~~~~~~~~~~~~~~~~~~~~~^^^^^^^^^^^^^^^^^^^^^^^^^^^^^^^^^^^^^^^^^^^^^^^^^^^^^^^^^^^^^^^^^^^^^^^^^^^^
  File "C:\Users\Eric\AppData\Local\Programs\Python\Python313\Lib\tkinter\__init__.py", line 2459, in __init__
    self.tk = _tkinter.create(screenName, baseName, className, interactive, wantobjects, useTk, sync, use)
              ~~~~~~~~~~~~~~~^^^^^^^^^^^^^^^^^^^^^^^^^^^^^^^^^^^^^^^^^^^^^^^^^^^^^^^^^^^^^^^^^^^^^^^^^^^^^
_tkinter.TclError: Can't find a usable init.tcl in the following directories: 
    C:/Users/Eric/AppData/Local/Programs/Python/Python313/lib/tcl8.6 C:/Users/Eric/AppData/Local/Programs/Python/lib/tcl8.6 C:/Users/Eric/AppData/Local/Programs/lib/tcl8.6 C:/Users/Eric/AppData/Local/Programs/Python/library C:/Users/Eric/AppData/Local/Programs/library C:/Users/Eric/AppData/Local/Programs/tcl8.6.14/library C:/Users/Eric/AppData/Local/tcl8.6.14/library



This probably means that Tcl wasn't installed properly.

2025-09-26 16:36:09,844 - nutrition_generator.main - INFO - Démarrage de l'application
2025-09-26 16:36:10,196 - nutrition_generator.main - ERROR - Erreur fatale: Can't find a usable init.tcl in the following directories: 
    C:/Users/Eric/AppData/Local/Programs/Python/Python313/lib/tcl8.6 C:/Users/Eric/AppData/Local/Programs/Python/lib/tcl8.6 C:/Users/Eric/AppData/Local/Programs/lib/tcl8.6 C:/Users/Eric/AppData/Local/Programs/Python/library C:/Users/Eric/AppData/Local/Programs/library C:/Users/Eric/AppData/Local/Programs/tcl8.6.14/library C:/Users/Eric/AppData/Local/tcl8.6.14/library



This probably means that Tcl wasn't installed properly.
Traceback (most recent call last):
  File "c:\Users\Eric\Documents\Fiche-nutrition\nutrition_generator\main.py", line 138, in main
    app = MainWindow()
  File "c:\Users\Eric\Documents\Fiche-nutrition\nutrition_generator\gui\main_window.py", line 24, in __init__
    super().__init__()
    ~~~~~~~~~~~~~~~~^^
  File "C:\Users\Eric\Documents\Fiche-nutrition\.venv\Lib\site-packages\customtkinter\windows\ctk_tk.py", line 40, in __init__
    CTK_PARENT_CLASS.__init__(self, **pop_from_dict_by_set(kwargs, self._valid_tk_constructor_arguments))
    ~~~~~~~~~~~~~~~~~~~~~~~~~^^^^^^^^^^^^^^^^^^^^^^^^^^^^^^^^^^^^^^^^^^^^^^^^^^^^^^^^^^^^^^^^^^^^^^^^^^^^
  File "C:\Users\Eric\AppData\Local\Programs\Python\Python313\Lib\tkinter\__init__.py", line 2459, in __init__
    self.tk = _tkinter.create(screenName, baseName, className, interactive, wantobjects, useTk, sync, use)
              ~~~~~~~~~~~~~~~^^^^^^^^^^^^^^^^^^^^^^^^^^^^^^^^^^^^^^^^^^^^^^^^^^^^^^^^^^^^^^^^^^^^^^^^^^^^^
_tkinter.TclError: Can't find a usable init.tcl in the following directories: 
    C:/Users/Eric/AppData/Local/Programs/Python/Python313/lib/tcl8.6 C:/Users/Eric/AppData/Local/Programs/Python/lib/tcl8.6 C:/Users/Eric/AppData/Local/Programs/lib/tcl8.6 C:/Users/Eric/AppData/Local/Programs/Python/library C:/Users/Eric/AppData/Local/Programs/library C:/Users/Eric/AppData/Local/Programs/tcl8.6.14/library C:/Users/Eric/AppData/Local/tcl8.6.14/library



This probably means that Tcl wasn't installed properly.

2025-09-26 16:36:40,265 - nutrition_generator.main - INFO - Démarrage de l'application
2025-09-26 16:36:40,611 - nutrition_generator.main - ERROR - Erreur fatale: Can't find a usable init.tcl in the following directories: 
    C:/Users/Eric/AppData/Local/Programs/Python/Python313/lib/tcl8.6 C:/Users/Eric/AppData/Local/Programs/Python/lib/tcl8.6 C:/Users/Eric/AppData/Local/Programs/lib/tcl8.6 C:/Users/Eric/AppData/Local/Programs/Python/library C:/Users/Eric/AppData/Local/Programs/library C:/Users/Eric/AppData/Local/Programs/tcl8.6.14/library C:/Users/Eric/AppData/Local/tcl8.6.14/library



This probably means that Tcl wasn't installed properly.
Traceback (most recent call last):
  File "c:\Users\Eric\Documents\Fiche-nutrition\nutrition_generator\main.py", line 138, in main
    app = MainWindow()
  File "c:\Users\Eric\Documents\Fiche-nutrition\nutrition_generator\gui\main_window.py", line 24, in __init__
    super().__init__()
    ~~~~~~~~~~~~~~~~^^
  File "C:\Users\Eric\Documents\Fiche-nutrition\.venv\Lib\site-packages\customtkinter\windows\ctk_tk.py", line 40, in __init__
    CTK_PARENT_CLASS.__init__(self, **pop_from_dict_by_set(kwargs, self._valid_tk_constructor_arguments))
    ~~~~~~~~~~~~~~~~~~~~~~~~~^^^^^^^^^^^^^^^^^^^^^^^^^^^^^^^^^^^^^^^^^^^^^^^^^^^^^^^^^^^^^^^^^^^^^^^^^^^^
  File "C:\Users\Eric\AppData\Local\Programs\Python\Python313\Lib\tkinter\__init__.py", line 2459, in __init__
    self.tk = _tkinter.create(screenName, baseName, className, interactive, wantobjects, useTk, sync, use)
              ~~~~~~~~~~~~~~~^^^^^^^^^^^^^^^^^^^^^^^^^^^^^^^^^^^^^^^^^^^^^^^^^^^^^^^^^^^^^^^^^^^^^^^^^^^^^
_tkinter.TclError: Can't find a usable init.tcl in the following directories: 
    C:/Users/Eric/AppData/Local/Programs/Python/Python313/lib/tcl8.6 C:/Users/Eric/AppData/Local/Programs/Python/lib/tcl8.6 C:/Users/Eric/AppData/Local/Programs/lib/tcl8.6 C:/Users/Eric/AppData/Local/Programs/Python/library C:/Users/Eric/AppData/Local/Programs/library C:/Users/Eric/AppData/Local/Programs/tcl8.6.14/library C:/Users/Eric/AppData/Local/tcl8.6.14/library



This probably means that Tcl wasn't installed properly.

2025-09-26 16:39:50,354 - nutrition_generator.main - INFO - Démarrage de l'application
2025-09-26 16:40:40,122 - nutrition_generator.main - INFO - Application fermée normalement
2025-09-26 17:13:44,192 - nutrition_generator.main - INFO - Démarrage de l'application
2025-09-26 17:16:11,187 - nutrition_generator.main - INFO - Application fermée normalement
2025-09-26 17:21:07,861 - nutrition_generator.main - INFO - Démarrage de l'application
2025-09-26 17:22:14,852 - nutrition_generator.main - INFO - Application fermée normalement
2025-09-26 17:25:27,384 - nutrition_generator.main - INFO - Démarrage de l'application
2025-09-26 17:26:00,642 - nutrition_generator.main - INFO - Application fermée normalement
2025-09-26 17:27:14,733 - nutrition_generator.main - INFO - Démarrage de l'application
2025-09-26 17:27:28,872 - nutrition_generator.main - INFO - Application fermée normalement
2025-09-26 17:27:31,702 - nutrition_generator.main - INFO - Démarrage de l'application
2025-09-26 17:27:56,496 - nutrition_generator.main - INFO - Application fermée normalement
2025-09-26 17:29:06,016 - nutrition_generator.main - INFO - Démarrage de l'application
2025-09-26 17:29:30,111 - nutrition_generator.main - INFO - Application fermée normalement
2025-09-26 17:30:49,880 - nutrition_generator.main - INFO - Démarrage de l'application
2025-09-26 17:31:52,757 - nutrition_generator.main - INFO - Application fermée normalement
2025-09-26 17:34:39,254 - nutrition_generator.main - INFO - Démarrage de l'application
2025-09-26 17:35:15,256 - nutrition_generator.main - INFO - Application fermée normalement
2025-09-26 17:40:46,707 - nutrition_generator.main - INFO - Démarrage de l'application
2025-09-26 17:41:43,584 - nutrition_generator.main - INFO - Application fermée normalement
2025-09-26 17:43:06,096 - nutrition_generator.main - INFO - Démarrage de l'application
2025-09-26 17:43:33,577 - nutrition_generator.main - INFO - Application fermée normalement
2025-09-26 17:44:01,534 - nutrition_generator.main - INFO - Démarrage de l'application
2025-09-26 17:44:29,150 - nutrition_generator.main - INFO - Application fermée normalement
2025-09-26 17:49:46,507 - nutrition_generator.main - INFO - Démarrage de l'application
2025-09-26 17:53:06,410 - nutrition_generator.main - INFO - Démarrage de l'application
2025-09-26 17:54:51,312 - nutrition_generator.main - INFO - Application fermée normalement
2025-09-26 17:54:52,139 - nutrition_generator.main - INFO - Application fermée normalement
2025-09-26 18:00:28,090 - nutrition_generator.main - INFO - Démarrage de l'application
2025-09-26 18:00:53,125 - nutrition_generator.main - INFO - Application fermée normalement
2025-09-26 18:04:06,402 - nutrition_generator.main - INFO - Démarrage de l'application
2025-09-26 18:04:09,073 - nutrition_generator.main - INFO - Application fermée normalement
2025-09-26 18:12:51,675 - nutrition_generator.main - INFO - Démarrage de l'application
2025-09-26 18:34:57,472 - nutrition_generator.main - INFO - Démarrage de l'application
2025-09-26 18:35:49,441 - nutrition_generator.main - INFO - Application fermée normalement
2025-09-26 19:10:35,974 - nutrition_generator.main - INFO - Démarrage de l'application
2025-09-26 19:11:17,158 - nutrition_generator.main - INFO - Application fermée normalement
2025-09-26 20:20:47,489 - __main__ - INFO - Démarrage de l'application
2025-09-26 20:20:47,489 - __main__ - ERROR - Erreur fatale: attempted relative import with no known parent package
Traceback (most recent call last):
  File "c:\Users\Eric\Documents\Fiche-nutrition\nutrition_generator\main.py", line 135, in main
    from .gui.main_window import MainWindow
ImportError: attempted relative import with no known parent package
2025-09-26 20:20:52,637 - __main__ - INFO - Démarrage de l'application
2025-09-26 20:20:52,637 - __main__ - ERROR - Erreur fatale: attempted relative import with no known parent package
Traceback (most recent call last):
  File "c:\Users\Eric\Documents\Fiche-nutrition\nutrition_generator\main.py", line 135, in main
    from .gui.main_window import MainWindow
ImportError: attempted relative import with no known parent package
2025-09-26 20:28:02,493 - __main__ - INFO - Démarrage de l'application
2025-09-26 20:29:32,782 - __main__ - INFO - Application fermée normalement
2025-09-26 21:14:56,241 - __main__ - INFO - Démarrage de l'application
2025-09-26 21:16:33,444 - __main__ - INFO - Application fermée normalement
2025-09-26 21:38:54,664 - __main__ - INFO - Démarrage de l'application
2025-09-26 21:40:03,517 - __main__ - INFO - Application fermée normalement
2025-09-26 21:56:24,937 - __main__ - INFO - Démarrage de l'application
2025-09-26 21:58:23,486 - __main__ - INFO - Application fermée normalement
2025-09-26 22:10:24,875 - __main__ - INFO - Démarrage de l'application
2025-09-26 22:11:52,383 - __main__ - INFO - Application fermée normalement
